## Wrapping Errors

Let's look at a helpful error handling pattern:

```go
package main

import (
	"fmt"

	"github.com/pkg/errors"
)

// AppError is a custom error type
type AppError struct {
	State int
}

// Error implements the error interface
func (c *AppError) Error() string {
	return fmt.Sprintf("App Error, State: %d", c.State)
}

func main() {
	// Make the function call and validate the error
	if err := firstCall(10); err != nil {
		// Use type as context to determine cause
		switch v := errors.Cause(err).(type) {
		case *AppError:
			// We got our custom error type
			fmt.Println("Custom App Error:", v.State)
		default:
			// We got a non-sepcific error type
			fmt.Println("Default Error")
		}

		// Display the stack trace for the error
		fmt.Println("\nStack Trace\n*************************************")
		fmt.Printf("%+v\n", err)

		fmt.Println("\nNo Trace\n*************************************")
		fmt.Printf("%v\n", err)
	}
}

// firstCall makes a call to secondCall and wraps any errors
func firstCall(i int) error {
	if err := secondCall(i); err != nil {
		return errors.Wrapf(err, "firstCall->secondCall(%d)", i)
	}

	return nil
}

// secondCall makes a call to thirdCall and wraps any errors
func secondCall(_ int) error {
	if err := thirdCall(); err != nil {
		return errors.Wrap(err, "secondCall->thirdCall()")
	}

	return nil
}

// thirdCall creates an error value we'll validate
func thirdCall() error {
	return &AppError{99}
}
```

Errors get wrapped as they move up the function stack, preserving context and helping trace the error's origin. `errors.Cause` is used to determine the root cause of an error, allowing for specific actions based on the error type, like handling `AppError` differently.